Workbook
Name AmortizaciónInterés: -IPMT('Prestamo 10 años'!TasaInterés/12,'Prestamo 10 años'!NúmeroDePago,'Prestamo 10 años'!NúmeroDePagos,'Prestamo 10 años'!CantidadPréstamo)
Name AmortizaciónInterés: -IPMT('Prestamo 15 años'!TasaInterés/12,'Prestamo 15 años'!NúmeroDePago,'Prestamo 15 años'!NúmeroDePagos,'Prestamo 15 años'!CantidadPréstamo)
Name AmortizaciónInterés: -IPMT(TasaInterés/12,NúmeroDePago,NúmeroDePagos,CantidadPréstamo)
Name AñosPréstamo: 'Prestamo 10 años'!$D$6
Name AñosPréstamo: 'Prestamo 15 años'!$D$6
Name AñosPréstamo: 'Prestamo 5 años'!$D$6
Name ÁreaImpresión_ESTABLECIDA: OFFSET('Prestamo 10 años'!$B$1,,,'Prestamo 10 años'!ÚltimaFila,'Prestamo 10 años'!ÚltimaColumna)
Name ÁreaImpresión_ESTABLECIDA: OFFSET('Prestamo 15 años'!$B$1,,,'Prestamo 15 años'!ÚltimaFila,'Prestamo 15 años'!ÚltimaColumna)
Name ÁreaImpresión_ESTABLECIDA: OFFSET('Prestamo 5 años'!$B$1,,,ÚltimaFila,ÚltimaColumna)
Name CantidadPréstamo: 'Prestamo 10 años'!$D$4
Name CantidadPréstamo: 'Prestamo 15 años'!$D$4
Name CantidadPréstamo: 'Prestamo 5 años'!$D$4
Name Capital: -PPMT('Prestamo 10 años'!TasaInterés/12,'Prestamo 10 años'!NúmeroDePago,'Prestamo 10 años'!NúmeroDePagos,'Prestamo 10 años'!CantidadPréstamo)
Name Capital: -PPMT('Prestamo 15 años'!TasaInterés/12,'Prestamo 15 años'!NúmeroDePago,'Prestamo 15 años'!NúmeroDePagos,'Prestamo 15 años'!CantidadPréstamo)
Name Capital: -PPMT(TasaInterés/12,NúmeroDePago,NúmeroDePagos,CantidadPréstamo)
Name CosteTotalPréstamo: 'Prestamo 10 años'!$H$7
Name CosteTotalPréstamo: 'Prestamo 15 años'!$H$7
Name CosteTotalPréstamo: 'Prestamo 5 años'!$H$7
Name FechaDePago: DATE(YEAR('Prestamo 10 años'!FechaInicioPréstamo),MONTH('Prestamo 10 años'!FechaInicioPréstamo)+'Prestamo 10 años'!NúmeroDePago,DAY('Prestamo 10 años'!FechaInicioPréstamo))
Name FechaDePago: DATE(YEAR('Prestamo 15 años'!FechaInicioPréstamo),MONTH('Prestamo 15 años'!FechaInicioPréstamo)+'Prestamo 15 años'!NúmeroDePago,DAY('Prestamo 15 años'!FechaInicioPréstamo))
Name FechaDePago: DATE(YEAR(FechaInicioPréstamo),MONTH(FechaInicioPréstamo)+NúmeroDePago,DAY(FechaInicioPréstamo))
Name FechaInicioPréstamo: 'Prestamo 10 años'!$D$7
Name FechaInicioPréstamo: 'Prestamo 15 años'!$D$7
Name FechaInicioPréstamo: 'Prestamo 5 años'!$D$7
Name FilaEncabezados: ROW('Prestamo 10 años'!$9:$9)
Name FilaEncabezados: ROW('Prestamo 15 años'!$9:$9)
Name FilaEncabezados: ROW('Prestamo 5 años'!$9:$9)
Name Intereses_Total: 'Prestamo 10 años'!$H$6
Name Intereses_Total: 'Prestamo 15 años'!$H$6
Name Intereses_Total: 'Prestamo 5 años'!$H$6
Name NúmeroDePago: ROW()-'Prestamo 10 años'!FilaEncabezados
Name NúmeroDePago: ROW()-'Prestamo 15 años'!FilaEncabezados
Name NúmeroDePago: ROW()-FilaEncabezados
Name NúmeroDePagos: 'Prestamo 10 años'!$H$5
Name NúmeroDePagos: 'Prestamo 15 años'!$H$5
Name NúmeroDePagos: 'Prestamo 5 años'!$H$5
Name PagoMensual: -PMT('Prestamo 10 años'!TasaInterés/12,'Prestamo 10 años'!NúmeroDePagos,'Prestamo 10 años'!CantidadPréstamo)
Name PagoMensual: -PMT('Prestamo 15 años'!TasaInterés/12,'Prestamo 15 años'!NúmeroDePagos,'Prestamo 15 años'!CantidadPréstamo)
Name PagoMensual: -PMT(TasaInterés/12,NúmeroDePagos,CantidadPréstamo)
Name PréstamoNoPagado: IF('Prestamo 10 años'!NúmeroDePago<='Prestamo 10 años'!NúmeroDePagos,1,0)
Name PréstamoNoPagado: IF('Prestamo 15 años'!NúmeroDePago<='Prestamo 15 años'!NúmeroDePagos,1,0)
Name PréstamoNoPagado: IF(NúmeroDePago<=NúmeroDePagos,1,0)
Name PréstamoPagado: IF('Prestamo 10 años'!CantidadPréstamo*'Prestamo 10 años'!TasaInterés*'Prestamo 10 años'!AñosPréstamo*'Prestamo 10 años'!FechaInicioPréstamo>0,1,0)
Name PréstamoPagado: IF('Prestamo 15 años'!CantidadPréstamo*'Prestamo 15 años'!TasaInterés*'Prestamo 15 años'!AñosPréstamo*'Prestamo 15 años'!FechaInicioPréstamo>0,1,0)
Name PréstamoPagado: IF(CantidadPréstamo*TasaInterés*AñosPréstamo*FechaInicioPréstamo>0,1,0)
Name SaldoFinal: -FV('Prestamo 10 años'!TasaInterés/12,'Prestamo 10 años'!NúmeroDePago,-'Prestamo 10 años'!PagoMensual,'Prestamo 10 años'!CantidadPréstamo)
Name SaldoFinal: -FV('Prestamo 15 años'!TasaInterés/12,'Prestamo 15 años'!NúmeroDePago,-'Prestamo 15 años'!PagoMensual,'Prestamo 15 años'!CantidadPréstamo)
Name SaldoFinal: -FV(TasaInterés/12,NúmeroDePago,-PagoMensual,CantidadPréstamo)
Name TasaInterés: 'Prestamo 10 años'!$D$5
Name TasaInterés: 'Prestamo 15 años'!$D$5
Name TasaInterés: 'Prestamo 5 años'!$D$5
Name TítuloDeColumna1: Préstamo[[#Headers],[N.° de pago]]
Name TítuloDeColumna1: Préstamo[[#Headers],[N.° de pago]]
Name TítuloDeColumna1: Préstamo[[#Headers],[N.° de pago]]
Name TítuloDeColumna1: Préstamo[[#Headers],[N.° de pago]]
Name TítuloDeColumna1: Préstamo[[#Headers],[N.° de pago]]
Name TítuloDeColumna1: Préstamo[[#Headers],[N.° de pago]]
Name TítuloDeColumna1: Préstamo[[#Headers],[N.° de pago]]
Name TítuloDeColumna1: Préstamo[[#Headers],[N.° de pago]]
Name TítuloDeFilaRegión2..H6: 'Prestamo 10 años'!$F$4

Sheet Cuadro de cargas
A1: Cantidad | B1: Descripción | C1: BTU | D1: Watt | E1: No. Horas día | F1: Energía diaria Wh/d | G1: Factor carga | H1: Energía diaria Wh/d | I1: No. Dias | J1: Energía mensual kWh/mes | K1: Cargas críticas | L1: Energía diaria Wh/d | O1: Wh | P1: 1 | Q1: 2 | R1: 3 | S1: 4 | T1: 5 | U1: 6 | V1: 7 | W1: 8 | X1: 9 | Y1: 10 | Z1: 11 | AA1: 12 | AB1: 13 | AC1: 14 | AD1: 15 | AE1: 16 | AF1: 17 | AG1: 18 | AH1: 19 | AI1: 20 | AJ1: 21 | AK1: 22 | AL1: 23 | AM1: 24 | AN1: Total
A2: 1 | B2: AC principal | C2: 24 | D2: 2000 | E2: 24 | F2: =+D2*E2*A2 -> 48000 | G2: 0.6 | H2: =+F2*G2 -> 28800 | I2: 30 | J2: =+(H2*I2)/1000 -> 864 | K2: 1 | L2: =+H2*K2 -> 28800 | O2: AC cuarto ppal | P2: =+D2*G2 -> 1200 | Q2: =+P2 -> 1200 | R2: =+Q2 -> 1200 | S2: =+R2 -> 1200 | T2: =+S2 -> 1200 | U2: =+T2 -> 1200 | V2: =+U2 -> 1200 | W2: =+V2 -> 1200 | X2: =+W2 -> 1200 | ... AM2: =+AL2 -> 1200 | AN2: =+SUM(P2:AM2) -> 28800
A3: 1 | B3: AC closet principal | C3: 18 | D3: 1500 | E3: 18 | F3: =+D3*E3*A3 -> 27000 | G3: 0.6 | H3: =+F3*G3 -> 16200 | I3: 30 | J3: =+(H3*I3)/1000 -> 486 | L3: =+H3*K3 -> 0 | O3: TV | P3: 0 | Q3: =+P3 -> 0 | R3: =+Q3 -> 0 | S3: =+R3 -> 0 | AH3: =+D13*G13*A13 -> 0 | AI3: =+AH3 -> 0 | AJ3: =+AI3 -> 0 | AK3: =+AJ3 -> 0 | AN3: =+SUM(P3:AM3) -> 0
A4: 5 | B4: Luces | D4: 30 | E4: 12 | F4: =+D4*E4*A4 -> 1800 | G4: 0.3 | H4: =+F4*G4 -> 540 | I4: 30 | J4: =+(H4*I4)/1000 -> 16.2 | K4: 1 | L4: =+H4*K4 -> 540 | O4: Luces | S4: =+D4*G4 -> 9 | T4: =+S4 -> 9 | U4: =+T4 -> 9 | AG4: =+S4 -> 9 | AH4: =+AG4 -> 9 | AI4: =+AH4 -> 9 | AJ4: =+AI4 -> 9 | AK4: =+AJ4 -> 9 | AN4: =+SUM(P4:AM4) -> 72
A5: 1 | B5: Nevera | D5: 250 | E5: 24 | F5: =+D5*E5*A5 -> 6000 | G5: 0.3 | H5: =+F5*G5 -> 1800 | I5: 30 | J5: =+(H5*I5)/1000 -> 54 | K5: 1 | L5: =+H5*K5 -> 1800 | O5: NEVECON | P5: =+D5*G5 -> 75 | Q5: =+$P$5 -> 75 | R5: =+$P$5 -> 75 | S5: =+$P$5 -> 75 | T5: =+$P$5 -> 75 | U5: =+$P$5 -> 75 | V5: =+$P$5 -> 75 | W5: =+$P$5 -> 75 | X5: =+$P$5 -> 75 | ... AM5: =+$P$5 -> 75 | AN5: =+SUM(P5:AM5) -> 1800
O7: Total | P7: =+SUM(P2:P6) -> 1275 | Q7: =+SUM(Q2:Q6) -> 1275 | R7: =+SUM(R2:R6) -> 1275 | S7: =+SUM(S2:S6) -> 1284 | T7: =+SUM(T2:T6) -> 1284 | U7: =+SUM(U2:U6) -> 1284 | V7: =+SUM(V2:V6) -> 1275 | W7: =+SUM(W2:W6) -> 1275 | ... AM7: =+SUM(AM2:AM6) -> 1275 | AN7: =+SUM(P7:AM7) -> 30672
A9: 1 | B9: Lavadora | D9: 200 | E9: 4 | F9: =+D9*E9*A9 -> 800 | G9: 0.5 | H9: =+F9*G9 -> 400 | I9: 20 | J9: =+(H9*I9)/1000 -> 8 | L9: =+H9*K9 -> 0
A10: 1 | B10: Secadora | D10: 2000 | E10: 4 | F10: =+D10*E10*A10 -> 8000 | G10: 0.5 | H10: =+F10*G10 -> 4000 | I10: 20 | J10: =+(H10*I10)/1000 -> 80 | L10: =+H10*K10 -> 0
A11: 1 | B11: Máquina de hielo | D11: 200 | E11: 2 | F11: =+D11*E11*A11 -> 400 | G11: 0.3 | H11: =+F11*G11 -> 120 | I11: 30 | J11: =+(H11*I11)/1000 -> 3.6 | L11: =+H11*K11 -> 0
A14: 1 | B14: Impresora | D14: 100 | E14: 2 | F14: =+D14*E14*A14 -> 200 | G14: 0.3 | H14: =+F14*G14 -> 60 | I14: 20 | J14: =+(H14*I14)/1000 -> 1.2 | L14: =+H14*K14 -> 0
A15: 1 | B15: Monitor | D15: 100 | E15: 4 | F15: =+D15*E15*A15 -> 400 | G15: 0.3 | H15: =+F15*G15 -> 120 | I15: 30 | J15: =+(H15*I15)/1000 -> 3.6 | L15: =+H15*K15 -> 0
A18: 10 | B18: Luces piscina | D18: 20 | E18: 8 | F18: =+D18*E18*A18 -> 1600 | G18: 0.3 | H18: =+F18*G18 -> 480 | I18: 30 | J18: =+(H18*I18)/1000 -> 14.4 | K18: 0 | L18: =+H18*K18 -> 0
A19: 1 | B19: Cargador volvo | D19: 7000 | E19: 4 | F19: =+D19*E19*A19 -> 28000 | G19: 0.3 | H19: =+F19*G19 -> 8400 | I19: 20 | J19: =+(H19*I19)/1000 -> 168 | L19: =+H19*K19 -> 0
A20: 1 | B20: Cargador carro golf | D20: 7000 | E20: 4 | F20: =+D20*E20*A20 -> 28000 | G20: 0.3 | H20: =+F20*G20 -> 8400 | I20: 20 | J20: =+(H20*I20)/1000 -> 168 | L20: =+H20*K20 -> 0
A22: 1 | B22: Sistema sonido sala | D22: 500 | E22: 4 | F22: =+D22*E22*A22 -> 2000 | G22: 0.3 | H22: =+F22*G22 -> 600 | I22: 15 | J22: =+(H22*I22)/1000 -> 9 | L22: =+H22*K22 -> 0
A23: 1 | B23: Nevera de vinos 12 botellas | D23: 100 | E23: 24 | F23: =+D23*E23*A23 -> 2400 | G23: 0.3 | H23: =+F23*G23 -> 720 | I23: 30 | J23: =+(H23*I23)/1000 -> 21.6 | L23: =+H23*K23 -> 0
F26: =+SUM(F2:F2) -> 48000 | H26: =+SUM(H2:H23) -> 70640 | J26: =+SUM(J2:J23) -> 1897.6 | L26: =+SUM(L2:L23) -> 31140
D27: =+#REF!+D4+D5+D8+(A12*D12)+(A13*D13)+(A16*D16)+(A17*D17)+(A21*D21) -> #REF! | F27: =+F26/1000 -> 48 | H27: =+H26/1000 -> 70.64 | J27: =+J26/30 -> 63.253333 | L27: =+L26/1000 -> 31.14
H28: Adicional | J28: 0.1 | L28: 0.1
H29: Energía diaria final | J29: =+J27*(1+J28) -> 69.578667 | K29: kWh-dia | L29: =+L27*(1+L28) -> 34.254
E30: =14000/(51.2) -> 273.4375 | H30: Energía mensual final | J30: =+J29*30 -> 2087.36 | K30: kWh-mes
E31: =+E30*1.25 -> 341.79688
B33: Área m2 | D33: =+D34*D35 -> 14.884
B34: Largo m | D34: 6.1 | G34: Pp= | H34: =+(H37/(H38*H39))*1000 -> 16136.054 | I34: Wp | K34: Ficha Técnica Panel
B35: Ancho m | D35: 2.44 | G35: Np= | H35: =+ROUNDUP(H34/L36,0) -> 24
G36: I = | H36: =+H37/H40 -> 1.4495556 | I36: Ah | K36: Pm= | L36: 700 | M36: W
B37: Área del Panel | D37: =+D38*D39 -> 3.106352 | G37: Ed | H37: =+J29 -> 69.578667 | I37: kWhd | K37: Vmp= | L37: 40.99 | M37: V
B38: Largo m | D38: 2.384 | G38: HSP | H38: 5.39 | I38: horas | K38: Imp= | L38: 13.54 | M38: A
B39: Ancho m | D39: 1.303 | G39: PR | H39: 0.8 | K39: Voc= | L39: 49.72 | M39: V
G40: V= | H40: 48 | I40: V | K40: Isc= | L40: 14.12 | M40: A
B41: No paneles | D41: =+D33/D37 -> 4.7914724 | G41: Potencia de los paneles | H41: =+H35*L36 -> 16800 | I41: Wp | K41: Dimensiones
B42: Potencia Panel | D42: 700 | G42: Potencia en DC inversores | H42: =+H43*1.4 -> 8400 | I42: Wp | K42: Largo | L42: 2.3 | M42: m
B43: Pp | D43: =+D42*4 -> 2800 | G43: Potencia en AC inversores | H43: 6000 | I43: w | K43: Espesor | L43: 31 | M43: mm
K44: Ancho | L44: =1.134+0.02 -> 1.154 | M44: m
K45: Área | L45: =+(L42*(L44+0.03+0.03)) -> 2.7922 | M45: m2

Sheet Datos2
A1: 1. Calcular el promedio de consumo eléctrico mensual | C1: NIC | D1: 6826712
A2: Mes kWh-mes
B4: =+D1 -> 6826712 | C4: Total
A5: 45870 | B5: 2142 | C5: =+B5 -> 2142 | N5: 45870 | O5: 45901 | P5: 45931 | Q5: 45962 | R5: 45992 | S5: 46023 | T5: 46054 | U5: 46082 | V5: 46113 | W5: 46143 | X5: 46174 | Y5: 46204 | Z5: 46235 | AA5: Promedio mes | AB5: Promedio dia
A6: 45901 | B6: 2063 | C6: =+B6 -> 2063 | G6: 12hrs | I6: Consumo Actual | M6: Consumo actual | N6: 2142 | O6: 2063 | P6: 1931 | Q6: 1439 | R6: 1428 | S6: 1562 | T6: 1231 | U6: 1361 | V6: 1712 | W6: 1565 | X6: 2143 | Y6: 2131 | Z6: 2409 | AA6: =+AVERAGE(N6:Z6) -> 1778.2308 | AB6: =+AA6/30 -> 59.274359
A7: 45931 | B7: 1931 | C7: =+B7 -> 1931 | M7: Costo energía | N7: =+(N6*Tarifas!X7)/1000*1.2 -> 2331.9183 | O7: =+(O6*Tarifas!Y7)/1000*1.2 -> 2335.6296 | P7: =+(P6*Tarifas!Z7)/1000*1.2 -> 2186.2782 | Q7: =+(Q6*Tarifas!AA7)/1000*1.2 -> 1629.1667 | R7: =+(R6*Tarifas!AB7)/1000*1.2 -> 1616.7131 | S7: =+(S6*Tarifas!AC7)/1000*1.2 -> 1758.4871 | T7: =+(T6*Tarifas!AD7)/1000*1.2 -> 1308.3708 | U7: =+(U6*Tarifas!AE7)/1000*1.2 -> 1446.5252 | ... Z7: =+(Z6*Tarifas!AJ7)/1000*1.2 -> 2300.8744
A8: 45962 | B8: 1439 | C8: =+B8 -> 1439 | M8: Consumo a cubrir con energía solar | N8: =+Producción!J8 -> 2150.5786 | O8: =+Producción!K8 -> 1982.636 | P8: =+Producción!L8 -> 2360.8296 | Q8: =+Producción!M8 -> 2144.5576 | R8: =+Producción!N8 -> 2079.2997 | S8: =+Producción!O8 -> 2090.0679 | T8: =+Producción!P8 -> 2224.0865 | U8: =+Producción!Q8 -> 2191.452 | ... Z8: =+Producción!V8 -> 2146.1897 | AA8: =+AVERAGE(P8:Z8) -> 2070.1202
A9: 45992 | B9: 1428 | C9: =+B9 -> 1428 | M9: % consumo cubierto con energía solar | N9: =+N8/N6 -> 1.004005 | O9: =+O8/O6 -> 0.9610451 | P9: =+P8/P6 -> 1.2225943 | Q9: =+Q8/Q6 -> 1.490311 | R9: =+R8/R6 -> 1.4560922 | S9: =+S8/S6 -> 1.3380716 | T9: =+T8/T6 -> 1.8067315 | U9: =+U8/U6 -> 1.6101778 | ... AA9: =+AA8/AA6 -> 1.164146
A10: 46023 | B10: 1562 | C10: =+B10 -> 1562
A11: 46054 | B11: 1231 | C11: =+B11 -> 1231
A12: 46082 | B12: 1361 | C12: =+B12 -> 1361
A13: 46113 | B13: 1712 | C13: =+B13 -> 1712
A14: 46143 | B14: 1565 | C14: =+B14 -> 1565
A15: 46174 | B15: 2143 | C15: =+B15 -> 2143
A16: 46204 | B16: 2131 | C16: =+B16 -> 2131
A17: 46235 | B17: 2409 | C17: =+B17 -> 2409
A18: Promedio mensual (kWh-mes) | B18: =+AVERAGE(B7:B17) -> 1719.2727 | C18: 1849.3077
A19: Promedio diario (kWh-dia) | B19: =+B18/30 -> 57.309091 | C19: =+C18/30 -> 61.64359
A20: Límite de producción | B20: 1.2 | C20: 1.2
A21: Pp | B21: =+(B19*B20*1000)/(J44*Cálculos!D6) -> 15943.797 | C21: =+(C20*1000)/(J44*Cálculos!D6) -> 278.20711 | H21: I
A22: Inversor kW | C22: 10 | H22: Imax
H23: Rtamb=
H24: R20°C=
H25: Calibre
B26: Local | H26: Total
B27: Cap instalada AC | H27: =+SUM(C27:G27) -> 0
B28: PP instalada | H28: =+SUM(C28:G28) -> 0
A29: 2. Escoger el nivel de voltaje del módulo fotovoltáico | B29: Pot exportación | H29: =+SUM(C29:G29) -> 0
C30: =12*610 -> 7320 | D30: =24*610 -> 14640 | E30: =+E28/610 -> 0 | F30: =12*610 -> 7320 | G30: =+G28/610 -> 0 | H30: =+H28/610 -> 0
A31: Potencia demandada (W) | B31: Tension (V) | C31: Nivel de voltaje seleccionado
A32: Menor de 1500 W | B32: 12, 24 o 48
A33: 1500 - 5000 W | B33: 24 o 48 | C33: 48
A34: Mayor de 5000 W | B34: 120 o 300
A37: 3. Ubicación del sistema solar fotovoltáico
A39: Latitud | B39: 10.5831
A40: Longitud | B40: -74.4821
A43: 4. Horas Sol Pico
I44: Promedio | J44: =+AVERAGE(A56:O56) -> 5.3916667
I45: Máx | J45: =+MAX(A56:O56) -> 6.04
I46: Mín | J46: =+MIN(A56:O56) -> 4.72
...

Sheet Cálculos
A1: 1. | B1: Hallar potencia Paneles Solares | C1: Pp= | D1: =+(D4/(D5*D6))*1000 -> 15943.797 | E1: Wp | G1: Ficha Técnica Panel | M1: Ficha Técnica Batería
C2: Np= | D2: =+ROUND(D1/H3,0) -> 22 | E2: =+D1/H3 -> 21.991444 | F2: =43*730 -> 31390
C3: I = | D3: =+D4/D7 -> 1.4327273 | E3: Ah | G3: Pm= | H3: 725 | I3: W | M3: Pdmaxe | N3: 0.7
C4: Ed | D4: =+Datos2!B19*Datos2!B20 -> 68.770909 | E4: kWhd | G4: Vmp= | H4: 40.99 | I4: V | M4: Pdmaxd | N4: 0.15
C5: HSP | D5: =+Datos2!J44 -> 5.3916667 | E5: horas | G5: Imp= | H5: 13.54 | I5: A | M5: V | N5: 6 | O5: V
C6: PR | D6: 0.8 | G6: Voc= | H6: 49.72 | I6: V | M6: I | N6: 300 | O6: Ah
C7: V= | D7: =+Datos2!C33 -> 48 | E7: V | G7: Isc= | H7: 14.12 | I7: A | M7: FCT (Factor de corrección de Temperatura) | N7: 1
C8: Potencia de los paneles Wp | D8: =+D2*H3 -> 15950 | E8: =+E2*H3 -> 15943.797 | G8: Dimensiones
C9: Potencia en DC inversores Wp | D9: =+(D22*B24) -> 15600 | G9: Largo | H9: 2.3 | I9: m
C10: Potencia en AC inversores W | D10: =+(D23*B24) -> 12000 | G10: Espesor | H10: 31 | I10: mm
G11: Ancho | H11: =1.134+0.02 -> 1.154 | I11: m
B12: Pp= Potencia del Panel | G12: Área | H12: 3.1 | I12: m2 | M12: Pdmaxe= Profundidad de descarga max estacionaria (FT) | N12: Valor constante
B13: Ed, max= Energia diaria + 15% | M13: Pdmaxd= Profundidad de descarga max diaria (FT) | N13: Valor constante
B14: HSP= Horas de sol pico, tomados del software de la NASA
B15: PR = performance Ratio
B16: Pm= Potencia del modulo solar (Tomado de la FT) | G16: Corrección por temperatura
B17: Np= No de paneles requerido | G17: Temp max amb | H17: 75
G18: Temp STC | H18: 25
G19: Delta Temp | H19: =+H17-H18 -> 50
G20: Potencia
A21: 2. | B21: Calcular el inversor | C21: % Sobredimensionamiento | D21: 0.3 | G21: Coef Pmax | H21: -0.0035
B22: Inversor 1 | C22: Pmax= | D22: =+D23*(1+D21) -> 15600 | E22: W | G22: Delta Pot | H22: =+H21*H19 -> -0.175
B23: Cantidad | C23: Pnom= | D23: 12000 | E23: W | G23: Pmc= | H23: =+H3*(100%+H22) -> 598.125 | I23: W
B24: 1 | C24: Imax DC= | D24: 30 | E24: A | G24: Voc
B25: No Paneles aproximados por MPPT | C25: IscDC= | D25: 37.5 | E25: A | G25: Coef Voc | H25: -0.00275
B26: =+ROUND(D2/(D30*B24),0) -> 4 | C26: VnomDC= | D26: 370 | E26: V | G26: Delta Voc | H26: =+H25*H19 -> -0.1375
C27: Inom AC= | D27: =D23/(D29*1.732) -> 31.492757 | E27: A | G27: Voc= | H27: =+H6*(100%+H26) -> 42.8835 | I27: V | J27: Vmp= | K27: =+H4*(100%+H26) -> 35.353875 | L27: V
C28: I max AC= | D28: 96 | E28: A
C29: Vac= | D29: 220 | E29: V | G29: Isc
C30: MPPT | D30: 6 | E30: A | G30: Coef Isc | H30: 0.00045
C31: String | D31: 2 | G31: Delta Isc | H31: =+H30*H19 -> 0.0225
G32: Isc= | H32: =+H7*(100%+H31) -> 14.4377 | I32: Amp | J32: Imp= | K32: =+H5*(100%+H31) -> 13.84465
C33: % Sobredimensionamiento | D33: 0.35
B34: Inversor 2 | C34: Pmax= | D34: =+D35*(1+D33) -> 8100 | E34: W
B35: Cantidad | C35: Pnom= | D35: 6000 | E35: W
B36: 1 | C36: Imax DC= | D36: 0 | E36: A
B37: No Paneles aproximados por MPPT | C37: IscDC= | D37: 0 | E37: A
B38: 0 | C38: VnomDC= | D38: 0 | E38: V
C39: Inom AC= | D39: 0 | E39: A
C40: I max AC= | D40: 0 | E40: A
...

Sheet Área

Sheet SIGO GoodWe
A3: Detallw Servicio llave en mano | B3: Precio de venta antes IVA | C3: Precio de Venta Iva Incluido | D3: PV antes de Iva | E3: PV Iva incluido | G3: Descripción | H3: Precio de venta antes IVA | I3: Precio de Venta Iva Incluido
A4: Suministro de equipos de energía renovable | B4: 19286571 | C4: 19370171 | D4: =+B4 -> 19286571 | E4: =D4 -> 19286571 | G4: Grupo generador | H4: =+#REF! -> #REF! | I4: =+#REF! -> #REF! | K4: 12176683
A5: Suministro de materiales y equipos | B5: 8206074.6 | C5: 9278591.5 | D5: =+B5 -> 8206074.6 | E5: =+C5 -> 9278591.5 | F5: =B5/2 -> 4103037.3 | G5: Descripción | H5: Precio de venta antes IVA | I5: Precio de Venta Iva Incluido | K5: =E4-K4 -> 7109888
A6: Servicio de diseño | B6: 5151515.2 | C6: 6130303 | D6: =C6/1.19 -> 5151515.2 | E6: =D6*1.19 -> 6130303 | G6: Total | H6: =+D13+H4 -> #REF! | I6: =+E13+I4 -> #REF!
A7: Servicio de instalación | B7: 4909090.9 | C7: 4969401.5 | D7: =+B7 -> 4909090.9 | E7: =+C22 -> 4950730.5
A8: Suministro de estructura | B8: 3576900 | C8: 4256511 | D8: =+B8 -> 3576900 | E8: =D8*1.19 -> 4256511
A9: Certificación Retie | B9: 1969697 | C9: 2343939.4 | D9: =+B9 -> 1969697 | E9: =D9*1.19 -> 2343939.4 | G9: =E12-D12 -> 3636191.7
A10: Suministro de medidor bidireccional | B10: 1666666.7 | C10: 1983333.3 | D10: =+B10 -> 1666666.7 | E10: =D10*1.19 -> 1983333.3 | G10: =D12/2 -> 22837803
A11: Trámites ante entidades | B11: 909090.91 | C11: 1081818.2 | D11: =+B11 -> 909090.91 | E11: =D11*1.19 -> 1081818.2 | G11: =D12/5 -> 9135121.2
A12: Total general | B12: 45675606 | C12: 49414069 | D12: =+SUM(D3:D11) -> 45675606 | E12: =+SUM(E3:E11) -> 49311798
F13: =E14/4 -> 0
A16: Servicio de instalación | C16: =+B7 -> 4909090.9
A17: Costo Directo | B17: =+SUM(B18:B20) -> 0.12 | C17: =+C16/(1+SUM(B18:B20)) -> 4383116.9
A18: Administración | B18: 0.05 | C18: =+C17*B18 -> 219155.84 | F18: Flujo de caja | G18: Porcentaje | H18: Valor antes de IVA | I18: Valor con IVA
A19: Imprevistos | B19: 0.02 | C19: =+C17*B19 -> 87662.338 | F19: Anticipo | G19: 0.35 | H19: =+$D$12*G19 -> 15986462 | I19: =$E$12*G19 -> 17259129
A20: Utilidad | B20: 0.05 | C20: =+C17*B20 -> 219155.84 | F20: Con llegada de paneles | G20: 0.25 | H20: =+$D$12*G20 -> 11418902 | I20: =$E$12*G20 -> 12327949
A21: Iva | B21: 0.19 | C21: =+C20*B21 -> 41639.61 | F21: Con llegada de inversor | G21: 0.2 | H21: =+$D$12*G21 -> 9135121.2 | I21: =$E$12*G21 -> 9862359.6
C22: =+SUM(C17:C21) -> 4950730.5 | F22: Instalacion aprobada | G22: 0.2 | H22: =+$D$12*G22 -> 9135121.2 | I22: =$E$12*G22 -> 9862359.6
E25: =E14-D14 -> 0 | F25: =+SUM(I19:I22) -> 49311798
E26: =D14/2 -> 0
E27: =D14/5 -> 0
B28: 25384068
B29: 20513846
B30: 14948373
B31: 9200000
B32: 3962104.6
B33: 2738461.5
B34: 2615384.6
B35: 2000000
B36: 1846153.8
B37: =SUM(B28:B36) -> 83208392

Sheet Capex GoodWe
C1: Margen | D1: Factor | Q1: Tiempo reposición | S1: =10*12 -> 120 | T1: meses
B2: Equipos renovable | C2: 0.34 | D2: =1-C2 -> 0.66
B3: Planta eléctrica | C3: 0.34 | D3: =1-C3 -> 0.66 | F3: =12000/(1.73*220) -> 31.529164 | G3: =F3*1.25 -> 39.411456 | H3: =360000/730 -> 493.15068
B4: Instalación | C4: 0.34 | D4: =1-C4 -> 0.66 | J4: 4000
B5: Diseños y trámites | C5: 0.34 | D5: =1-C5 -> 0.66 | F5: =I26+I30+I41+I54+I83 -> 2839947.5
B6: Obra civil | C6: 0.34 | D6: =1-C6 -> 0.66
A8: Item | B8: Descripción | C8: Un | D8: Inv 1 | E8: Inv 2 | F8: Cant total | G8: IVA | H8: CU | I8: CT antes IVA | J8: CT Iva Incluido | K8: PV | L8: PV antes IVA | M8: PV Iva Incluido | N8: Categoría Sigo | O8: Pareto | P8: Costo/Winstalado | Q8: Precio/Winstalado | R8: Tiempo de reposición | S8: Reposición Empresa | T8: Reposición Cliente
A9: 1 | B9: Equipos principales | I9: =+SUM(I10:I15) -> 13333037 | J9: =+SUM(J10:J15) -> 13502954 | L9: =+SUM(L10:L15) -> 20201571 | M9: =+SUM(M10:M15) -> 20459021 | O9: =+K9/$K$117 -> 0 | P9: =+H9/$C$180 -> 0 | Q9: =+K9/$C$180 -> 0 | V9: V.U. Antes IVA | W9: V.U | X9: Cantidad/panel | Y9: V.T. antes IVA | Z9: V.T./panel | AA9: =+M9 -> 20459021 | AB9: =+J9 -> 13502954
A10: 1.1 | B10: PANEL SOLAR 725 W | C10: Un | D10: =+Cálculos!D2 -> 22 | E10: 0 | F10: =+D10+E10 -> 22 | G10: 0 | H10: =370000 -> 370000 | I10: =+H10*F10 -> 8140000 | J10: =+I10*(1+G10) -> 8140000 | K10: =+H10/$D$2 -> 560606.06 | L10: =+K10*F10 -> 12333333 | M10: =+L10*(1+G10) -> 12333333 | N10: Suministro de equipos de energía renovable | R10: =20*12 -> 240 | S10: =+IF(R10=0,0,H10/R10) -> 1541.6667 | T10: =+IF(R10=0,0,K10/R10) -> 2335.8586 | U10: Riel AS-DR-01A-5100 | V10: 123655 | W10: =+V10*1.19 -> 147149.45 | X10: 0.52 | Y10: =+V10*X10 -> 64300.6 | Z10: =+W10*X10 -> 76517.714
A11: 1.2 | B11: [GW12KLV-MT] Inversor trifásico 12kw 208-240Vac 3 MPPT con DC switch y Wifi GoodWe | C11: Un | D11: 1 | E11: 0 | F11: =+D11+E11 -> 1 | G11: 0 | H11: 4298736.9 | I11: =+H11*F11 -> 4298736.9 | J11: =+I11*(1+G11) -> 4298736.9 | K11: =+H11/$D$2 -> 6513237.7 | L11: =+K11*F11 -> 6513237.7 | M11: =+L11*(1+G11) -> 6513237.7 | N11: Suministro de equipos de energía renovable | R11: =20*12 -> 240 | S11: =+IF(R11=0,0,H11/R11) -> 17911.404 | T11: =+IF(R11=0,0,K11/R11) -> 27138.49 | U11: Middle clamp AS-DMC / 30 mm | V11: 5668 | W11: =+V11*1.19 -> 6744.92 | X11: 2.017 | Y11: =+V11*X11 -> 11432.356 | Z11: =+W11*X11 -> 13604.504
A12: 1.3 | B12: Smart Meter | C12: Un | D12: 1 | E12: 0 | F12: =+D12+E12 -> 1 | G12: 0.19 | H12: =88*3300 -> 290400 | I12: =+H12*F12 -> 290400 | J12: =+I12*(1+G12) -> 345576 | K12: =+H12/$D$2 -> 440000 | L12: =+K12*F12 -> 440000 | M12: =+L12*(1+G12) -> 523600 | N12: Suministro de equipos de energía renovable | R12: =20*12 -> 240 | S12: =+IF(R12=0,0,H12/R12) -> 1210 | T12: =+IF(R12=0,0,K12/R12) -> 1833.3333
A13: 1.4 | B13: [GW14.3-BAT-LV-G10] Batería LFP(LiFePO4) 51.2 Vdc 280 Ah [with aerosol] Goodwe | C13: Un | D13: 0 | E13: 0 | F13: =+D13+E13 -> 0 | G13: 0.19 | H13: 6667000 | I13: =+H13*F13 -> 0 | J13: =+I13*(1+G13) -> 0 | K13: =+H13/$D$2 -> 10101515 | L13: =+K13*F13 -> 0 | M13: =+L13*(1+G13) -> 0 | N13: Suministro de equipos de almacenamiento | R13: =20*12 -> 240 | S13: =+IF(R13=0,0,H13/R13) -> 27779.167 | T13: =+IF(R13=0,0,K13/R13) -> 42089.646 | U13: Enclamp AS-DEC / 30 mm | V13: 5668 | W13: =+V13*1.19 -> 6744.92 | X13: 0.367 | Y13: =+V13*X13 -> 2080.156 | Z13: =+W13*X13 -> 2475.3856
A14: 1.5 | B14: HV418100 12S Gabinete | C14: Un | D14: 0 | E14: 0 | F14: =+D14+E14 -> 0 | G14: 0.19 | H14: 4784000 | I14: =+H14*F14 -> 0 | J14: =+I14*(1+G14) -> 0 | K14: =+H14/$D$2 -> 7248484.8 | L14: =+K14*F14 -> 0 | M14: =+L14*(1+G14) -> 0 | N14: Suministro de materiales y equipos | R14: =20*12 -> 240 | S14: =+IF(R14=0,0,H14/R14) -> 19933.333 | T14: =+IF(R14=0,0,K14/R14) -> 30202.02 | U14: Clip tierra | V14: 1030 | W14: =+V14*1.19 -> 1225.7 | X14: 0.5 | Y14: =+V14*X14 -> 515 | Z14: =+W14*X14 -> 612.85
A15: 1.6 | B15: EQUIPOS DE MEDIDA TC´S | C15: Un | D15: 3 | E15: 0 | F15: =+D15+E15 -> 3 | G15: 0.19 | H15: =61*3300 -> 201300 | I15: =+H15*F15 -> 603900 | J15: =+I15*(1+G15) -> 718641 | K15: =+H15/$D$2 -> 305000 | L15: =+K15*F15 -> 915000 | M15: =+L15*(1+G15) -> 1088850 | N15: Suministro de materiales y equipos
A16: 2 | B16: Estructura Metálica | I16: =+SUM(I17:I25) -> 2360754 | J16: =+SUM(J17:J25) -> 2809297.3 | K16: 0 | L16: =+SUM(L17:L25) -> 3576900 | M16: =+SUM(M17:M25) -> 4256511 | O16: =+K16/$K$117 -> 0 | P16: =+H16/$C$180 -> 0 | Q16: =+K16/$C$180 -> 0 | S16: =+IF(R16=0,0,H16/R16) -> 0 | T16: =+IF(R16=0,0,K16/R16) -> 0 | U16: Ground Clamp | V16: 5744 | W16: =+V16*1.19 -> 6835.36 | X16: 0.183 | Y16: =+V16*X16 -> 1051.152 | Z16: =+W16*X16 -> 1250.8709 | AA16: =+M16 -> 4256511 | AB16: =+J16 -> 2809297.3
A17: 2.1 | B17: Riel de soporte aluminio anodizado 4,7 | C17: Un | D17: =0.61*D10 -> 13.42 | E17: =0.61*E10 -> 0 | F17: =+D17+E17 -> 13.42 | G17: 0.19 | H17: 100000 | I17: =+H17*F17 -> 1342000 | J17: =+I17*(1+G17) -> 1596980 | K17: =+H17/$D$2 -> 151515.15 | L17: =+K17*F17 -> 2033333.3 | M17: =+L17*(1+G17) -> 2419666.7 | N17: Suministro de estructura | R17: 0 | S17: =+IF(R17=0,0,H17/R17) -> 0 | T17: =+IF(R17=0,0,K17/R17) -> 0 | U17: Autoperforante | V17: 15457 | W17: =+V17*1.19 -> 18393.83 | X17: 0.5 | Y17: =+V17*X17 -> 7728.5 | Z17: =+W17*X17 -> 9196.915
A18: 2.2 | B18: Union de riel | C18: Un | D18: =0.33*D10 -> 7.26 | E18: =0.33*E10 -> 0 | F18: =+D18+E18 -> 7.26 | G18: 0.19 | H18: 6900 | I18: =+H18*F18 -> 50094 | J18: =+I18*(1+G18) -> 59611.86 | K18: =+H18/$D$2 -> 10454.545 | L18: =+K18*F18 -> 75900 | M18: =+L18*(1+G18) -> 90321 | N18: Suministro de estructura | P18: =+H18/$C$180 -> 0.4327702 | Q18: =+K18/$C$180 -> 0.65571242 | R18: 0 | S18: =+IF(R18=0,0,H18/R18) -> 0 | T18: =+IF(R18=0,0,K18/R18) -> 0 | U18: Unión de Riel | V18: 5733 | W18: =+V18*1.19 -> 6822.27 | X18: 0.46 | Y18: =+V18*X18 -> 2637.18 | Z18: =+W18*X18 -> 3138.2442
A19: 2.3 | B19: Mid Clamp | C19: Un | D19: =1.5*D10 -> 33 | E19: =2*E10 -> 0 | F19: =+D19+E19 -> 33 | G19: 0.19 | H19: 3500 | I19: =+H19*F19 -> 115500 | J19: =+I19*(1+G19) -> 137445 | K19: =+H19/$D$2 -> 5303.0303 | L19: =+K19*F19 -> 175000 | M19: =+L19*(1+G19) -> 208250 | N19: Suministro de estructura | R19: 0 | S19: =+IF(R19=0,0,H19/R19) -> 0 | T19: =+IF(R19=0,0,K19/R19) -> 0 | U19: Inclinación paneles | V19: 123655 | W19: =+V19*1.19 -> 147149.45 | X19: 0.8 | Y19: =+V19*X19 -> 98924 | Z19: =+W19*X19 -> 117719.56
A20: 2.4 | B20: End Clamp | C20: Un | D20: =1*D10 -> 22 | E20: =0.94*E10 -> 0 | F20: =+D20+E20 -> 22 | G20: 0.19 | H20: 3500 | I20: =+H20*F20 -> 77000 | J20: =+I20*(1+G20) -> 91630 | K20: =+H20/$D$2 -> 5303.0303 | L20: =+K20*F20 -> 116666.67 | M20: =+L20*(1+G20) -> 138833.33 | N20: Suministro de estructura | R20: 0 | S20: =+IF(R20=0,0,H20/R20) -> 0 | T20: =+IF(R20=0,0,K20/R20) -> 0 | U20: Dado | V20: 50000 | W20: =+V20*1.19 -> 59500 | X20: =8/5 -> 1.6 | Y20: =+V20*X20 -> 80000 | Z20: =+W20*X20 -> 95200 | AD20: CT ANTES IVA | AE20: =+I26+I30+I41+I54+I83+I134 -> 2889947.5 | AG20: 6715625
A21: 2.5 | B21: Chapa de tierra (Mid clamp) | C21: Un | D21: =+D19 -> 33 | E21: =0.5*E10 -> 0 | F21: =+D21+E21 -> 33 | G21: 0.19 | H21: 700 | I21: =+H21*F21 -> 23100 | J21: =+I21*(1+G21) -> 27489 | K21: =+H21/$D$2 -> 1060.6061 | L21: =+K21*F21 -> 35000 | M21: =+L21*(1+G21) -> 41650 | N21: Suministro de estructura | R21: 0 | S21: =+IF(R21=0,0,H21/R21) -> 0 | T21: =+IF(R21=0,0,K21/R21) -> 0 | Y21: =+SUM(Y10:Y20) -> 268668.94 | Z21: =+SUM(Z10:Z20) -> 319716.04 | AD21: CT IVA INCLUIDO | AE21: =+J26+J30+J41+J54+J83+J134 -> 3439037.6 | AG21: 7991595
A22: 2.6 | B22: Ground Lug | C22: Un | D22: =0.5*D10 -> 11 | E22: =0.94*E10 -> 0 | F22: =0.94*F10 -> 20.68 | G22: 0.19 | H22: 4500 | I22: =+H22*F22 -> 93060 | J22: =+I22*(1+G22) -> 110741.4 | K22: =+H22/$D$2 -> 6818.1818 | L22: =+K22*F22 -> 141000 | M22: =+L22*(1+G22) -> 167790 | N22: Suministro de estructura | P22: =+H22/$C$180 -> 0.28224143 | Q22: =+K22/$C$180 -> 0.42763854 | R22: 0 | S22: =+IF(R22=0,0,H22/R22) -> 0 | T22: =+IF(R22=0,0,K22/R22) -> 0 | X22: Imprevisto | Y22: 1 | Z22: 1
A23: 2.7 | B23: L Foot 85 mm | C23: Un | D23: =2*D10 -> 44 | E23: =1.79*E10 -> 0 | F23: =+D23+E23 -> 44 | G23: 0.19 | H23: 15000 | I23: =+H23*F23 -> 660000 | J23: =+I23*(1+G23) -> 785400 | K23: =+H23/$D$2 -> 22727.273 | L23: =+K23*F23 -> 1000000 | M23: =+L23*(1+G23) -> 1190000 | N23: Suministro de estructura | R23: 0 | S23: =+IF(R23=0,0,H23/R23) -> 0 | T23: =+IF(R23=0,0,K23/R23) -> 0 | Y23: =+Y21*Y22 -> 268668.94 | Z23: =+Z21*Z22 -> 319716.04
A24: 2.8 | B24: Dados | C24: Un | D24: 0 | E24: =1.8*E11 -> 0 | F24: =+D24+E24 -> 0 | G24: 0.19 | H24: 25000 | I24: =+H24*F24 -> 0 | J24: =+I24*(1+G24) -> 0 | K24: =+H24/$D$2 -> 37878.788 | L24: =+K24*F24 -> 0 | M24: =+L24*(1+G24) -> 0 | N24: Suministro de estructura
A25: 2.9 | B25: Riel de soporte aluminio anodizado 4,7 | C25: Un | D25: 0 | E25: =0.61*E18 -> 0 | F25: =+D25+E25 -> 0 | G25: 0.19 | H25: 115141 | I25: =+H25*F25 -> 0 | J25: =+I25*(1+G25) -> 0 | K25: =+H25/$D$2 -> 174456.06 | L25: =+K25*F25 -> 0 | M25: =+L25*(1+G25) -> 0 | N25: Suministro de estructura
A26: 3 | B26: Protecciones en DC | G26: 0.19 | I26: =+SUM(I27:I29) -> 344000 | J26: =+SUM(J27:J29) -> 409360 | L26: =+SUM(L27:L29) -> 521212.12 | M26: =+SUM(M27:M29) -> 620242.42 | P26: =+I26+I30+I41+I47+I54+I83 -> 2839947.5 | R26: 0 | S26: =+IF(R26=0,0,H26/R26) -> 0 | T26: =+IF(R26=0,0,K26/R26) -> 0 | AA26: =+M26 -> 620242.42 | AB26: =+J26 -> 409360
A27: 3.1 | B27: TABLERO BIFÁSICO TIPO RIEL DIN 18 PUESTOS SOBREPONER | C27: Un | D27: 1 | E27: 0 | F27: =+D27+E27 -> 1 | G27: 0.19 | H27: 150000 | I27: =+H27*F27 -> 150000 | J27: =+I27*(1+G27) -> 178500 | K27: =+H27/$D$3 -> 227272.73 | L27: =+K27*D27 -> 227272.73 | M27: =+L27*(1+G27) -> 270454.55 | N27: Suministro de materiales y equipos | R27: 0 | S27: =+IF(R27=0,0,H27/R27) -> 0 | T27: =+IF(R27=0,0,K27/R27) -> 0
A28: 3.2 | B28: DPS SOLAR 1000V TIPO RIEL DIN | C28: Un | D28: 2 | E28: 0 | F28: =+D28+E28 -> 2 | G28: 0.19 | H28: 60000 | I28: =+H28*F28 -> 120000 | J28: =+I28*(1+G28) -> 142800 | K28: =+H28/$D$3 -> 90909.091 | L28: =+K28*D28 -> 181818.18 | M28: =+L28*(1+G28) -> 216363.64 | N28: Suministro de materiales y equipos | P28: =+H28/$C$180 -> 3.7632191 | Q28: =+K28/$C$180 -> 5.7018472 | R28: 0 | S28: =+IF(R28=0,0,H28/R28) -> 0 | T28: =+IF(R28=0,0,K28/R28) -> 0
A29: 3.3 | B29: MINIBREAKERS 32A | C29: Un | D29: 2 | E29: 0 | F29: =+D29+E29 -> 2 | G29: 0.19 | H29: 37000 | I29: =+H29*F29 -> 74000 | J29: =+I29*(1+G29) -> 88060 | K29: =+H29/$D$3 -> 56060.606 | L29: =+K29*D29 -> 112121.21 | M29: =+L29*(1+G29) -> 133424.24 | N29: Suministro de materiales y equipos | R29: 0 | S29: =+IF(R29=0,0,H29/R29) -> 0 | T29: =+IF(R29=0,0,K29/R29) -> 0
A30: 4 | B30: Protecciones en AC | G30: 0.19 | I30: =+SUM(I31:I40) -> 397400 | J30: =+SUM(J31:J40) -> 472906 | L30: =+SUM(L31:L40) -> 602121.21 | M30: =+SUM(M31:M40) -> 716524.24 | S30: =+IF(R30=0,0,H30/R30) -> 0 | T30: =+IF(R30=0,0,K30/R30) -> 0 | AA30: =+M30 -> 716524.24 | AB30: =+J30 -> 472906
A31: 4.1 | B31: TABLERO BIFÁSICO TIPO RIEL DIN 18 PUESTOS SOBREPONER | C31: Un | D31: 1 | E31: 0 | F31: =+D31+E31 -> 1 | G31: 0.19 | H31: 150000 | I31: =+H31*F31 -> 150000 | J31: =+I31*(1+G31) -> 178500 | K31: =+H31/$D$3 -> 227272.73 | L31: =+K31*F31 -> 227272.73 | M31: =+L31*(1+G31) -> 270454.55 | N31: Suministro de materiales y equipos
A32: 4.2 | B32: FUSIBLE Y PORTA FUSIBLE DE BATERIAS | C32: Un | D32: 0 | E32: 0 | F32: =+D32+E32 -> 0 | G32: 0.19 | H32: 195000 | I32: =+H32*F32 -> 0 | J32: =+I32*(1+G32) -> 0 | K32: =+H32/$D$3 -> 295454.55 | L32: =+K32*F32 -> 0 | M32: =+L32*(1+G32) -> 0 | N32: Suministro de materiales y equipos | O32: =+K32/$K$117 -> 4.7305985 | R32: 0 | S32: =+IF(R32=0,0,H32/R32) -> 0 | T32: =+IF(R32=0,0,K32/R32) -> 0
A33: 4.3 | B33: MINIBREAKER AC 2X32A TIPO RIEL DIN | C33: Un | D33: 0 | E33: 0 | F33: =+D33+E33 -> 0 | G33: 0.19 | H33: 21439 | I33: =+H33*F33 -> 0 | J33: =+I33*(1+G33) -> 0 | K33: =+H33/$D$3 -> 32483.333 | L33: =+K33*F33 -> 0 | M33: =+L33*(1+G33) -> 0 | N33: Suministro de materiales y equipos | P33: =+H33/$C$180 -> 1.3446609 | Q33: =+K33/$C$180 -> 2.037365 | R33: 0 | S33: =+IF(R33=0,0,H33/R33) -> 0 | T33: =+IF(R33=0,0,K33/R33) -> 0
A34: 4.4 | B34: MINIBREAKER AC3X50A TIPO RIEL DIN | C34: Un | D34: 1 | E34: 0 | F34: =+D34+E34 -> 1 | G34: 0.19 | H34: 19000 | I34: =+H34*F34 -> 19000 | J34: =+I34*(1+G34) -> 22610 | K34: =+H34/$D$3 -> 28787.879 | L34: =+K34*F34 -> 28787.879 | M34: =+L34*(1+G34) -> 34257.576 | N34: Suministro de materiales y equipos | R34: 0 | S34: =+IF(R34=0,0,H34/R34) -> 0 | T34: =+IF(R34=0,0,K34/R34) -> 0
A35: 4.5 | B35: MINIBREAKER AC 3x200A TIPO RIEL DIN | C35: Un | D35: 0 | E35: 0 | F35: =+D35+E35 -> 0 | G35: 0.19 | H35: 396000 | I35: =+H35*F35 -> 0 | J35: =+I35*(1+G35) -> 0 | K35: =+H35/$D$3 -> 600000 | L35: =+K35*F35 -> 0 | M35: =+L35*(1+G35) -> 0 | N35: Suministro de materiales y equipos | R35: 0 | S35: =+IF(R35=0,0,H35/R35) -> 0 | T35: =+IF(R35=0,0,K35/R35) -> 0
A36: 4.6 | B36: DPS CLASE 2 TIPO RIEL DIN AC | C36: Un | D36: 1 | E36: 0 | F36: =+D36+E36 -> 1 | G36: 0.19 | H36: 147000 | I36: =+H36*F36 -> 147000 | J36: =+I36*(1+G36) -> 174930 | K36: =+H36/$D$3 -> 222727.27 | L36: =+K36*F36 -> 222727.27 | M36: =+L36*(1+G36) -> 265045.45 | N36: Suministro de materiales y equipos | O36: =+K36/$K$117 -> 3.5661435 | R36: 0 | S36: =+IF(R36=0,0,H36/R36) -> 0 | T36: =+IF(R36=0,0,K36/R36) -> 0
A37: 4.7 | B37: PROTECCIÓN ENCHUFABLE 2X32A | C37: Un | D37: 0 | E37: 0 | F37: =+D37+E37 -> 0 | G37: 0.19 | H37: 58824 | I37: =+H37*F37 -> 0 | J37: =+I37*(1+G37) -> 0 | K37: =+H37/$D$3 -> 89127.273 | L37: =+K37*F37 -> 0 | M37: =+L37*(1+G37) -> 0 | N37: Suministro de materiales y equipos | R37: 0 | S37: =+IF(R37=0,0,H37/R37) -> 0 | T37: =+IF(R37=0,0,K37/R37) -> 0
A38: 4.8 | B38: PROTECCIÓN ENCHUFABLE 3X50A | C38: Un | D38: 1 | E38: 0 | F38: =+D38+E38 -> 1 | G38: 0.19 | H38: 50000 | I38: =+H38*F38 -> 50000 | J38: =+I38*(1+G38) -> 59500 | K38: =+H38/$D$3 -> 75757.576 | L38: =+K38*F38 -> 75757.576 | M38: =+L38*(1+G38) -> 90151.515 | N38: Suministro de materiales y equipos | R38: 0 | S38: =+IF(R38=0,0,H38/R38) -> 0 | T38: =+IF(R38=0,0,K38/R38) -> 0
A39: 4.9 | B39: TABLERO GENERAL BAJA TENSION 24 CTOS TIPO ENCHUFABLE (Incluye 4 breaker 2x20 + 8 1x16 + 2 1x20) | C39: Un | D39: 0 | E39: 0 | F39: 0 | G39: 0.19 | I39: =+H39*F39 -> 0 | J39: =+I39*(1+G39) -> 0 | K39: =+H39/$D$3 -> 0 | L39: =+K39*F39 -> 0 | M39: =+L39*(1+G39) -> 0 | N39: Suministro de materiales y equipos | R39: 0 | S39: =+IF(R39=0,0,H39/R39) -> 0 | T39: =+IF(R39=0,0,K39/R39) -> 0
A40: 4.10 | B40: MINIBREAKER DE 1X2A TIPO RIEL DIN | C40: Un | D40: 1 | E40: 0 | F40: =+D40+E40 -> 1 | G40: 0.19 | H40: 31400 | I40: =+H40*F40 -> 31400 | J40: =+I40*(1+G40) -> 37366 | K40: =+H40/$D$3 -> 47575.758 | L40: =+K40*F40 -> 47575.758 | M40: =+L40*(1+G40) -> 56615.152 | N40: Suministro de materiales y equipos | R40: 0 | S40: =+IF(R40=0,0,H40/R40) -> 0 | T40: =+IF(R40=0,0,K40/R40) -> 0
A41: 5 | B41: Canalizaciones - registros | I41: =+SUM(I42:I46) -> 127300 | J41: =+SUM(J42:J46) -> 151487 | K41: 115842.86 | L41: =+SUM(L42:L46) -> 192878.79 | M41: =+SUM(M42:M46) -> 229525.76 | R41: 0 | S41: =+IF(R41=0,0,H41/R41) -> 0 | T41: =+IF(R41=0,0,K41/R41) -> 0 | AA41: =+M41 -> 229525.76 | AB41: =+J41 -> 151487
...

Sheet Ejecución
C2: Sem 1 | D2: Sem 2 | E2: Sem 3 | F2: Sem 4 | G2: Sem 5 | H2: Sem 6 | I2: Sem 7 | J2: Sem 8 | K2: Sem 9 | L2: Sem 10 | M2: Sem 11 | N2: Sem 12 | O2: Sem 13
B3: Orden de compra
B4: Diseño
B5: Compra de estructuras y materiales
B6: Instalación de estructura y materiales
B7: Compra de paneles e inversores
B8: Instalación de paneles e inversores
B9: Compra e instalación de bateria 1
B10: Compra e instalación de bateria 2
B11: Compra e instalación de bateria 3

Sheet Cronograma
B2: Descripción | C2: Sem 1 | D2: Sem 2 | E2: Sem 3 | F2: Sem 4 | G2: Sem 5 | H2: Sem 6
B3: Diseño
B4: Adquisición estructura
B5: Adquisición materiales
B6: Adquisición paneles
B7: Adquisición inversores
B8: Adquisición baterías
B9: Instalación estructura
B10: Instalación materiales
B11: Instalación de paneles
B12: Instalación de inversores
B13: Puesta en servicio sistema sin baterias
B14: Instalación de baterías
B15: Puesta en servicio sistema con baterías

Sheet Instalación
A1: Rendimiento
A2: No Paneles CCPP | B2: =+#REF! -> #REF! | C2: Horas Requeridas | D2: No Personas | E2: Horas Disponibles diarias | F2: No Días
A3: Horas por panel incluye cableado | B3: 3.5 | C3: =+B2*B3 -> #REF! | D3: 2 | E3: =8*D3 -> 16 | F3: =+C3/E3 -> #REF! | H3: No horas semanales | I3: =44*4.3 -> 189.2
A4: Sistema Eléctrico | B4: =+B2 -> #REF! | C4: Horas Requeridas | D4: No Personas | E4: Horas Disponibles diarias | F4: No Días
A5: Sistema AC CCPP | C5: =+F5*8*D5 -> 32 | D5: 2 | F5: 2
A6: Puesta en servicio CCPP | C6: =+F6*8*D6 -> 16 | D6: 2 | F6: 1
A7: Total Horas | C7: =+C3+C5+C6 -> #REF! | D7: 3 | E7: 8 | F7: =+(C7)/(D7*E7) -> #REF!
B9: Sueldo | C9: k | D9: Salario | E9: Salario horario/Diario | F9: No horas/No Días | G9: Total
A10: Técnicos fijos | B10: =2200000+250000+300000 -> 2750000 | C10: 1.5 | D10: =+B10*C10 -> 4125000 | E10: =+D10/I3 -> 21802.326 | F10: =+C7 -> #REF! | G10: =+E10*F10 -> #REF! | I10: 150000
A11: Técnicos por obra labor | B11: 0 | C11: 1.47 | D11: =+B11*C11 -> 0 | E11: =+D11/I3 -> 0 | F11: =+C8 -> 0 | G11: =+E11*F11 -> 0 | I11: =114*3 -> 342
A12: Ayudante | B12: 0 | C12: 1.47 | D12: =+B12*C12 -> 0 | E12: =+D12/I3 -> 0 | F12: 1.5 | G12: =+E12*F12 -> 0 | I12: =+I10/I11 -> 438.59649
A13: Supervisor | B13: 3300000 | C13: 1.5 | D13: =+B13*C13 -> 4950000 | E13: =+D13/I3 -> 26162.791 | F13: =+F10*40% -> #REF! | G13: =+E13*F13 -> #REF! | I13: =+I12*277 -> 121491.23
A14: Alimentacion | B14: 25000 | C14: =+D7 -> 3 | D14: =+B14*C14 -> 75000 | E14: =+D14 -> 75000 | F14: =+F7 -> #REF! | G14: =+E14*F14 -> #REF!
A15: Herramientas | B15: =4000000/12 -> 333333.33 | C15: 1 | D15: =+B15*C15 -> 333333.33 | E15: =+D15/I3 -> 1761.8041 | F15: =+F10 -> #REF! | G15: =+E15*F15 -> #REF!
A16: Peajes | B16: =9*20000 -> 180000 | C16: 0 | D16: =+B16*C16 -> 0 | E16: =+D16 -> 0 | F16: 1 | G16: =+E16*F16 -> 0
A17: Apartamento | B17: 200000 | C17: 0 | D17: =+B17*C17 -> 0 | E17: 0 | F17: 5 | G17: =+D17*F17 -> 0
A18: Transporte | B18: 60000 | C18: 1 | D18: =+B18*C18 -> 60000 | E18: =+D18 -> 60000 | F18: =+F7 -> #REF! | G18: =+E18*F18 -> #REF!
A19: Hidratación | B19: 10000 | C19: =+D7 -> 3 | D19: =+B19*C19 -> 30000 | E19: =+D19 -> 30000 | F19: =+F7 -> #REF! | G19: =+E19*F19 -> #REF!
A20: Dotación | B20: 355000 | C20: 1 | D20: =+B20*C20 -> 355000 | E20: =+D20/(6*180) -> 328.7037 | F20: =+F10 -> #REF! | G20: =+E20*F20 -> #REF!
A21: Andamios | B21: 350000 | C21: 1 | D21: =+B21*C21 -> 350000 | G21: =+D21 -> 350000
A22: Moto | G22: =+D22*E22*F22 -> 0
A23: Elementos para trabajo en altura | B23: 1642850 | C23: 18 | D23: =+B23/C23 -> 91269.444 | E23: =+D23/I3 -> 482.39664 | F23: =+F10 -> #REF! | G23: =+E23*F23 -> #REF!
G25: =+SUM(G10:G24) -> #REF!
G26: =+#REF! -> #REF!
G27: =+G25/G26 -> #REF!

Sheet Prestamo 5 años
B1: Calculadora de préstamos simple
L2: {=+TRANSPOSE(B10:B69)} -> 1 | M2: 2 | N2: 3 | O2: 4 | P2: 5 | Q2: 6 | R2: 7 | S2: 8 | T2: 9 | U2: 10 | V2: 11 | W2: 12 | X2: 13 | Y2: 14 | Z2: 15 | AA2: 16 | AB2: 17 | AC2: 18 | AD2: 19 | AE2: 20 | AF2: 21 | AG2: 22 | AH2: 23 | AI2: 24 | AJ2: 25 | AK2: 26 | AL2: 27 | AM2: 28 | AN2: 29 | AO2: 30 | AP2: 31 | AQ2: 32 | AR2: 33 | AS2: 34 | AT2: 35 | AU2: 36 | AV2: 37 | AW2: 38 | AX2: 39 | AY2: 40 | AZ2: 41 | BA2: 42 | BB2: 43 | BC2: 44 | BD2: 45 | BE2: 46 | BF2: 47 | BG2: 48 | BH2: 49 | BI2: 50 | BJ2: 51 | BK2: 52 | BL2: 53 | BM2: 54 | BN2: 55 | BO2: 56 | BP2: 57 | BQ2: 58 | BR2: 59 | BS2: 60
B3: Valores del préstamo | F3: Resumen del préstamo | K3: Capital | L3: {=+TRANSPOSE(F10:F69)} -> 420908.55 | M3: 429677.48 | N3: 438629.09 | O3: 447767.2 | P3: 457095.68 | Q3: 466618.51 | R3: 476339.72 | S3: 486263.47 | T3: 496393.96 | U3: 506735.5 | V3: 517292.49 | W3: 528069.41 | X3: 539070.86 | Y3: 550301.5 | Z3: 561766.12 | AA3: 573469.58 | AB3: 585416.86 | AC3: 597613.05 | AD3: 610063.32 | AE3: 622772.97 | AF3: 635747.41 | AG3: 648992.15 | AH3: 662512.82 | AI3: 676315.17 | AJ3: 690405.06 | AK3: 704788.5 | AL3: 719471.6 | AM3: 734460.59 | AN3: 749761.85 | AO3: 765381.89 | AP3: 781327.35 | AQ3: 797605 | AR3: 814221.77 | AS3: 831184.72 | AT3: 848501.07 | AU3: 866178.18 | AV3: 884223.56 | AW3: 902644.88 | AX3: 921449.98 | AY3: 940646.86 | AZ3: 960243.67 | BA3: 980248.74 | BB3: 1000670.6 | BC3: 1021517.9 | BD3: 1042799.5 | BE3: 1064524.5 | BF3: 1086702.1 | BG3: 1109341.7 | BH3: 1132453 | BI3: 1156045.8 | BJ3: 1180130.1 | BK3: 1204716.1 | BL3: 1229814.4 | BM3: 1255435.5 | BN3: 1281590.4 | BO3: 1308290.2 | BP3: 1335546.3 | BQ3: 1363370.1 | BR3: 1391773.7 | BS3: 1420769
B4: Importe del préstamo | D4: =+'Capex GoodWe'!M152 -> 49414069 | F4: Pago mensual | H4: =IFERROR(IF(PréstamoPagado,PagoMensual,""), "") -> 1450368.3 | K4: Intereses | L4: {=+TRANSPOSE(G10:G69)} -> 1029459.8 | M4: 1020690.8 | N4: 1011739.2 | O4: 1002601.1 | P4: 993272.64 | Q4: 983749.81 | R4: 974028.59 | S4: 964104.85 | T4: 953974.36 | U4: 943632.82 | V4: 933075.83 | W4: 922298.9 | X4: 911297.46 | Y4: 900066.81 | Z4: 888602.2 | AA4: 876898.74 | AB4: 864951.46 | AC4: 852755.27 | AD4: 840305 | AE4: 827595.35 | AF4: 814620.91 | AG4: 801376.17 | AH4: 787855.5 | AI4: 774053.15 | AJ4: 759963.25 | AK4: 745579.81 | AL4: 730896.72 | AM4: 715907.73 | AN4: 700606.47 | AO4: 684986.43 | AP4: 669040.97 | AQ4: 652763.32 | AR4: 636146.55 | AS4: 619183.59 | AT4: 601867.25 | AU4: 584190.14 | AV4: 566144.76 | AW4: 547723.44 | AX4: 528918.34 | AY4: 509721.46 | AZ4: 490124.65 | BA4: 470119.57 | BB4: 449697.73 | BC4: 428850.42 | BD4: 407568.8 | BE4: 385843.81 | BF4: 363666.22 | BG4: 341026.59 | BH4: 317915.3 | BI4: 294322.53 | BJ4: 270238.24 | BK4: 245652.2 | BL4: 220553.95 | BM4: 194932.82 | BN4: 168777.91 | BO4: 142078.11 | BP4: 114822.06 | BQ4: 86998.183 | BR4: 58594.638 | BS4: 29599.353
B5: Tasa de interés anual | D5: 0.25 | F5: Número de pagos | H5: =IFERROR(IF(PréstamoPagado,AñosPréstamo*12,""), "") -> 60 | K5: Saldo Capital | L5: {=+TRANSPOSE(H10:H69)} -> 48993160 | M5: 48563483 | N5: 48124854 | O5: 47677087 | P5: 47219991 | Q5: 46753372 | R5: 46277033 | S5: 45790769 | T5: 45294375 | U5: 44787640 | V5: 44270347 | W5: 43742278 | X5: 43203207 | Y5: 42652906 | Z5: 42091139 | AA5: 41517670 | AB5: 40932253 | AC5: 40334640 | AD5: 39724577 | AE5: 39101804 | AF5: 38466056 | AG5: 37817064 | AH5: 37154551 | AI5: 36478236 | AJ5: 35787831 | AK5: 35083043 | AL5: 34363571 | AM5: 33629110 | AN5: 32879349 | AO5: 32113967 | AP5: 31332639 | AQ5: 30535034 | AR5: 29720812 | AS5: 28889628 | AT5: 28041127 | AU5: 27174949 | AV5: 26290725 | AW5: 25388080 | AX5: 24466630 | AY5: 23525983 | AZ5: 22565740 | BA5: 21585491 | BB5: 20584820 | BC5: 19563302 | BD5: 18520503 | BE5: 17455978 | BF5: 16369276 | BG5: 15259935 | BH5: 14127481 | BI5: 12971436 | BJ5: 11791306 | BK5: 10586590 | BL5: 9356775.1 | BM5: 8101339.6 | BN5: 6819749.2 | BO5: 5511459 | BP5: 4175912.8 | BQ5: 2812542.6 | BR5: 1420769 | BS5: 4.7683716e-07
B6: Periodo del préstamo en años | D6: 5 | F6: Importe total de los intereses | H6: =IFERROR(IF(PréstamoPagado,CosteTotalPréstamo-CantidadPréstamo,""), "") -> 37608030 | J6: 1159 | K6: Seguros | L6: =+(L5/1000000)*$J$6 -> 56783.073 | M6: =+(M5/1000000)*$J$6 -> 56285.077 | N6: =+(N5/1000000)*$J$6 -> 55776.706 | O6: =+(O5/1000000)*$J$6 -> 55257.743 | P6: =+(P5/1000000)*$J$6 -> 54727.97 | Q6: =+(Q5/1000000)*$J$6 -> 54187.159 | R6: =+(R5/1000000)*$J$6 -> 53635.081 | S6: =+(S5/1000000)*$J$6 -> 53071.502 | ... BS6: =+(BS5/1000000)*$J$6 -> 5.5265427e-10
B7: Fecha de inicio del préstamo | D7: =TODAY() -> 46301 | F7: Coste total del préstamo | H7: =IFERROR(IF(PréstamoPagado,PagoMensual*NúmeroDePagos,""), "") -> 87022099 | K7: Total | L7: =+L3+L4+L6 -> 1507151.4 | M7: =+M3+M4+M6 -> 1506653.4 | N7: =+N3+N4+N6 -> 1506145 | O7: =+O3+O4+O6 -> 1505626.1 | P7: =+P3+P4+P6 -> 1505096.3 | Q7: =+Q3+Q4+Q6 -> 1504555.5 | R7: =+R3+R4+R6 -> 1504003.4 | S7: =+S3+S4+S6 -> 1503439.8 | ... BS7: =+BS3+BS4+BS6 -> 1450368.3
B9: N.° de pago | C9: Fecha de pago | D9: Saldo inicial | E9: Pago | F9: Capital | G9: Intereses | H9: Saldo final
B10: =IFERROR(IF(PréstamoNoPagado*PréstamoPagado,NúmeroDePago,""), "") -> 1 | C10: =IFERROR(IF(PréstamoNoPagado*PréstamoPagado,FechaDePago,""), "") -> 46332 | D10: =IFERROR(IF(PréstamoNoPagado*PréstamoPagado,ValorPréstamo,""), "") -> 49414069 | E10: =IFERROR(IF(PréstamoNoPagado*PréstamoPagado,PagoMensual,""), "") -> 1450368.3 | F10: =IFERROR(IF(PréstamoNoPagado*PréstamoPagado,Capital,""), "") -> 420908.55 | G10: =IFERROR(IF(PréstamoNoPagado*PréstamoPagado,AmortizaciónInterés,""), "") -> 1029459.8 | H10: =IFERROR(IF(PréstamoNoPagado*PréstamoPagado,SaldoFinal,""), "") -> 48993160
B11: =IFERROR(IF(PréstamoNoPagado*PréstamoPagado,NúmeroDePago,""), "") -> 2 | C11: =IFERROR(IF(PréstamoNoPagado*PréstamoPagado,FechaDePago,""), "") -> 46362 | D11: =IFERROR(IF(PréstamoNoPagado*PréstamoPagado,ValorPréstamo,""), "") -> 48993160 | E11: =IFERROR(IF(PréstamoNoPagado*PréstamoPagado,PagoMensual,""), "") -> 1450368.3 | F11: =IFERROR(IF(PréstamoNoPagado*PréstamoPagado,Capital,""), "") -> 429677.48 | G11: =IFERROR(IF(PréstamoNoPagado*PréstamoPagado,AmortizaciónInterés,""), "") -> 1020690.8 | H11: =IFERROR(IF(PréstamoNoPagado*PréstamoPagado,SaldoFinal,""), "") -> 48563483
B12: =IFERROR(IF(PréstamoNoPagado*PréstamoPagado,NúmeroDePago,""), "") -> 3 | C12: =IFERROR(IF(PréstamoNoPagado*PréstamoPagado,FechaDePago,""), "") -> 46393 | D12: =IFERROR(IF(PréstamoNoPagado*PréstamoPagado,ValorPréstamo,""), "") -> 48563483 | E12: =IFERROR(IF(PréstamoNoPagado*PréstamoPagado,PagoMensual,""), "") -> 1450368.3 | F12: =IFERROR(IF(PréstamoNoPagado*PréstamoPagado,Capital,""), "") -> 438629.09 | G12: =IFERROR(IF(PréstamoNoPagado*PréstamoPagado,AmortizaciónInterés,""), "") -> 1011739.2 | H12: =IFERROR(IF(PréstamoNoPagado*PréstamoPagado,SaldoFinal,""), "") -> 48124854
B13: =IFERROR(IF(PréstamoNoPagado*PréstamoPagado,NúmeroDePago,""), "") -> 4 | C13: =IFERROR(IF(PréstamoNoPagado*PréstamoPagado,FechaDePago,""), "") -> 46424 | D13: =IFERROR(IF(PréstamoNoPagado*PréstamoPagado,ValorPréstamo,""), "") -> 48124854 | E13: =IFERROR(IF(PréstamoNoPagado*PréstamoPagado,PagoMensual,""), "") -> 1450368.3 | F13: =IFERROR(IF(PréstamoNoPagado*PréstamoPagado,Capital,""), "") -> 447767.2 | G13: =IFERROR(IF(PréstamoNoPagado*PréstamoPagado,AmortizaciónInterés,""), "") -> 1002601.1 | H13: =IFERROR(IF(PréstamoNoPagado*PréstamoPagado,SaldoFinal,""), "") -> 47677087
B14: =IFERROR(IF(PréstamoNoPagado*PréstamoPagado,NúmeroDePago,""), "") -> 5 | C14: =IFERROR(IF(PréstamoNoPagado*PréstamoPagado,FechaDePago,""), "") -> 46452 | D14: =IFERROR(IF(PréstamoNoPagado*PréstamoPagado,ValorPréstamo,""), "") -> 47677087 | E14: =IFERROR(IF(PréstamoNoPagado*PréstamoPagado,PagoMensual,""), "") -> 1450368.3 | F14: =IFERROR(IF(PréstamoNoPagado*PréstamoPagado,Capital,""), "") -> 457095.68 | G14: =IFERROR(IF(PréstamoNoPagado*PréstamoPagado,AmortizaciónInterés,""), "") -> 993272.64 | H14: =IFERROR(IF(PréstamoNoPagado*PréstamoPagado,SaldoFinal,""), "") -> 47219991
B15: =IFERROR(IF(PréstamoNoPagado*PréstamoPagado,NúmeroDePago,""), "") -> 6 | C15: =IFERROR(IF(PréstamoNoPagado*PréstamoPagado,FechaDePago,""), "") -> 46483 | D15: =IFERROR(IF(PréstamoNoPagado*PréstamoPagado,ValorPréstamo,""), "") -> 47219991 | E15: =IFERROR(IF(PréstamoNoPagado*PréstamoPagado,PagoMensual,""), "") -> 1450368.3 | F15: =IFERROR(IF(PréstamoNoPagado*PréstamoPagado,Capital,""), "") -> 466618.51 | G15: =IFERROR(IF(PréstamoNoPagado*PréstamoPagado,AmortizaciónInterés,""), "") -> 983749.81 | H15: =IFERROR(IF(PréstamoNoPagado*PréstamoPagado,SaldoFinal,""), "") -> 46753372
B16: =IFERROR(IF(PréstamoNoPagado*PréstamoPagado,NúmeroDePago,""), "") -> 7 | C16: =IFERROR(IF(PréstamoNoPagado*PréstamoPagado,FechaDePago,""), "") -> 46513 | D16: =IFERROR(IF(PréstamoNoPagado*PréstamoPagado,ValorPréstamo,""), "") -> 46753372 | E16: =IFERROR(IF(PréstamoNoPagado*PréstamoPagado,PagoMensual,""), "") -> 1450368.3 | F16: =IFERROR(IF(PréstamoNoPagado*PréstamoPagado,Capital,""), "") -> 476339.72 | G16: =IFERROR(IF(PréstamoNoPagado*PréstamoPagado,AmortizaciónInterés,""), "") -> 974028.59 | H16: =IFERROR(IF(PréstamoNoPagado*PréstamoPagado,SaldoFinal,""), "") -> 46277033
B17: =IFERROR(IF(PréstamoNoPagado*PréstamoPagado,NúmeroDePago,""), "") -> 8 | C17: =IFERROR(IF(PréstamoNoPagado*PréstamoPagado,FechaDePago,""), "") -> 46544 | D17: =IFERROR(IF(PréstamoNoPagado*PréstamoPagado,ValorPréstamo,""), "") -> 46277033 | E17: =IFERROR(IF(PréstamoNoPagado*PréstamoPagado,PagoMensual,""), "") -> 1450368.3 | F17: =IFERROR(IF(PréstamoNoPagado*PréstamoPagado,Capital,""), "") -> 486263.47 | G17: =IFERROR(IF(PréstamoNoPagado*PréstamoPagado,AmortizaciónInterés,""), "") -> 964104.85 | H17: =IFERROR(IF(PréstamoNoPagado*PréstamoPagado,SaldoFinal,""), "") -> 45790769
B18: =IFERROR(IF(PréstamoNoPagado*PréstamoPagado,NúmeroDePago,""), "") -> 9 | C18: =IFERROR(IF(PréstamoNoPagado*PréstamoPagado,FechaDePago,""), "") -> 46574 | D18: =IFERROR(IF(PréstamoNoPagado*PréstamoPagado,ValorPréstamo,""), "") -> 45790769 | E18: =IFERROR(IF(PréstamoNoPagado*PréstamoPagado,PagoMensual,""), "") -> 1450368.3 | F18: =IFERROR(IF(PréstamoNoPagado*PréstamoPagado,Capital,""), "") -> 496393.96 | G18: =IFERROR(IF(PréstamoNoPagado*PréstamoPagado,AmortizaciónInterés,""), "") -> 953974.36 | H18: =IFERROR(IF(PréstamoNoPagado*PréstamoPagado,SaldoFinal,""), "") -> 45294375
B19: =IFERROR(IF(PréstamoNoPagado*PréstamoPagado,NúmeroDePago,""), "") -> 10 | C19: =IFERROR(IF(PréstamoNoPagado*PréstamoPagado,FechaDePago,""), "") -> 46605 | D19: =IFERROR(IF(PréstamoNoPagado*PréstamoPagado,ValorPréstamo,""), "") -> 45294375 | E19: =IFERROR(IF(PréstamoNoPagado*PréstamoPagado,PagoMensual,""), "") -> 1450368.3 | F19: =IFERROR(IF(PréstamoNoPagado*PréstamoPagado,Capital,""), "") -> 506735.5 | G19: =IFERROR(IF(PréstamoNoPagado*PréstamoPagado,AmortizaciónInterés,""), "") -> 943632.82 | H19: =IFERROR(IF(PréstamoNoPagado*PréstamoPagado,SaldoFinal,""), "") -> 44787640
B20: =IFERROR(IF(PréstamoNoPagado*PréstamoPagado,NúmeroDePago,""), "") -> 11 | C20: =IFERROR(IF(PréstamoNoPagado*PréstamoPagado,FechaDePago,""), "") -> 46636 | D20: =IFERROR(IF(PréstamoNoPagado*PréstamoPagado,ValorPréstamo,""), "") -> 44787640 | E20: =IFERROR(IF(PréstamoNoPagado*PréstamoPagado,PagoMensual,""), "") -> 1450368.3 | F20: =IFERROR(IF(PréstamoNoPagado*PréstamoPagado,Capital,""), "") -> 517292.49 | G20: =IFERROR(IF(PréstamoNoPagado*PréstamoPagado,AmortizaciónInterés,""), "") -> 933075.83 | H20: =IFERROR(IF(PréstamoNoPagado*PréstamoPagado,SaldoFinal,""), "") -> 44270347
B21: =IFERROR(IF(PréstamoNoPagado*PréstamoPagado,NúmeroDePago,""), "") -> 12 | C21: =IFERROR(IF(PréstamoNoPagado*PréstamoPagado,FechaDePago,""), "") -> 46666 | D21: =IFERROR(IF(PréstamoNoPagado*PréstamoPagado,ValorPréstamo,""), "") -> 44270347 | E21: =IFERROR(IF(PréstamoNoPagado*PréstamoPagado,PagoMensual,""), "") -> 1450368.3 | F21: =IFERROR(IF(PréstamoNoPagado*PréstamoPagado,Capital,""), "") -> 528069.41 | G21: =IFERROR(IF(PréstamoNoPagado*PréstamoPagado,AmortizaciónInterés,""), "") -> 922298.9 | H21: =IFERROR(IF(PréstamoNoPagado*PréstamoPagado,SaldoFinal,""), "") -> 43742278
... B369: =IFERROR(IF(PréstamoNoPagado*PréstamoPagado,NúmeroDePago,""), "") | C369: =IFERROR(IF(PréstamoNoPagado*PréstamoPagado,FechaDePago,""), "") | D369: =IFERROR(IF(PréstamoNoPagado*PréstamoPagado,ValorPréstamo,""), "") | E369: =IFERROR(IF(PréstamoNoPagado*PréstamoPagado,PagoMensual,""), "") | F369: =IFERROR(IF(PréstamoNoPagado*PréstamoPagado,Capital,""), "") | G369: =IFERROR(IF(PréstamoNoPagado*PréstamoPagado,AmortizaciónInterés,""), "") | H369: =IFERROR(IF(PréstamoNoPagado*PréstamoPagado,SaldoFinal,""), "")

Sheet Prestamo 10 años
B1: Calculadora de préstamos simple
L2: {=+TRANSPOSE(B10:B129)}
B3: Valores del préstamo | F3: Resumen del préstamo | K3: Capital | L3: {=+TRANSPOSE(F10:F129)}
B4: Importe del préstamo | D4: =+#REF! -> #REF! | F4: Pago mensual | H4: =IFERROR(IF(PréstamoPagado,PagoMensual,""), "") | K4: Intereses | L4: {=+TRANSPOSE(G10:G129)}
B5: Tasa de interés anual | D5: 0.13 | F5: Número de pagos | H5: =IFERROR(IF(PréstamoPagado,AñosPréstamo*12,""), "") | K5: Saldo Capital | L5: {=+TRANSPOSE(H10:H129)}
B6: Periodo del préstamo en años | D6: 10 | F6: Importe total de los intereses | H6: =IFERROR(IF(PréstamoPagado,CosteTotalPréstamo-CantidadPréstamo,""), "") | J6: 1159 | K6: Seguros | L6: =+(L5/1000000)*$J$6 -> #VALUE! | M6: =+(M5/1000000)*$J$6 -> #VALUE! | N6: =+(N5/1000000)*$J$6 -> #VALUE! | O6: =+(O5/1000000)*$J$6 -> #VALUE! | P6: =+(P5/1000000)*$J$6 -> #VALUE! | Q6: =+(Q5/1000000)*$J$6 -> #VALUE! | R6: =+(R5/1000000)*$J$6 -> #VALUE! | S6: =+(S5/1000000)*$J$6 -> #VALUE! | ... EA6: =+(EA5/1000000)*$J$6 -> #VALUE!
B7: Fecha de inicio del préstamo | D7: =TODAY() -> 46301 | F7: Coste total del préstamo | H7: =IFERROR(IF(PréstamoPagado,PagoMensual*NúmeroDePagos,""), "") | K7: Total | L7: =+L3+L4+L6 -> #VALUE! | M7: =+M3+M4+M6 -> #VALUE! | N7: =+N3+N4+N6 -> #VALUE! | O7: =+O3+O4+O6 -> #VALUE! | P7: =+P3+P4+P6 -> #VALUE! | Q7: =+Q3+Q4+Q6 -> #VALUE! | R7: =+R3+R4+R6 -> #VALUE! | S7: =+S3+S4+S6 -> #VALUE! | ... EA7: =+EA3+EA4+EA6 -> #VALUE!
B9: N.° de pago | C9: Fecha de pago | D9: Saldo inicial | E9: Pago | F9: Capital | G9: Intereses | H9: Saldo final
B10: =IFERROR(IF(PréstamoNoPagado*PréstamoPagado,NúmeroDePago,""), "") | C10: =IFERROR(IF(PréstamoNoPagado*PréstamoPagado,FechaDePago,""), "") | D10: =IFERROR(IF(PréstamoNoPagado*PréstamoPagado,ValorPréstamo,""), "") | E10: =IFERROR(IF(PréstamoNoPagado*PréstamoPagado,PagoMensual,""), "") | F10: =IFERROR(IF(PréstamoNoPagado*PréstamoPagado,Capital,""), "") | G10: =IFERROR(IF(PréstamoNoPagado*PréstamoPagado,AmortizaciónInterés,""), "") | H10: =IFERROR(IF(PréstamoNoPagado*PréstamoPagado,SaldoFinal,""), "")
B11: =IFERROR(IF(PréstamoNoPagado*PréstamoPagado,NúmeroDePago,""), "") | C11: =IFERROR(IF(PréstamoNoPagado*PréstamoPagado,FechaDePago,""), "") | D11: =IFERROR(IF(PréstamoNoPagado*PréstamoPagado,ValorPréstamo,""), "") | E11: =IFERROR(IF(PréstamoNoPagado*PréstamoPagado,PagoMensual,""), "") | F11: =IFERROR(IF(PréstamoNoPagado*PréstamoPagado,Capital,""), "") | G11: =IFERROR(IF(PréstamoNoPagado*PréstamoPagado,AmortizaciónInterés,""), "") | H11: =IFERROR(IF(PréstamoNoPagado*PréstamoPagado,SaldoFinal,""), "")
B12: =IFERROR(IF(PréstamoNoPagado*PréstamoPagado,NúmeroDePago,""), "") | C12: =IFERROR(IF(PréstamoNoPagado*PréstamoPagado,FechaDePago,""), "") | D12: =IFERROR(IF(PréstamoNoPagado*PréstamoPagado,ValorPréstamo,""), "") | E12: =IFERROR(IF(PréstamoNoPagado*PréstamoPagado,PagoMensual,""), "") | F12: =IFERROR(IF(PréstamoNoPagado*PréstamoPagado,Capital,""), "") | G12: =IFERROR(IF(PréstamoNoPagado*PréstamoPagado,AmortizaciónInterés,""), "") | H12: =IFERROR(IF(PréstamoNoPagado*PréstamoPagado,SaldoFinal,""), "")
B13: =IFERROR(IF(PréstamoNoPagado*PréstamoPagado,NúmeroDePago,""), "") | C13: =IFERROR(IF(PréstamoNoPagado*PréstamoPagado,FechaDePago,""), "") | D13: =IFERROR(IF(PréstamoNoPagado*PréstamoPagado,ValorPréstamo,""), "") | E13: =IFERROR(IF(PréstamoNoPagado*PréstamoPagado,PagoMensual,""), "") | F13: =IFERROR(IF(PréstamoNoPagado*PréstamoPagado,Capital,""), "") | G13: =IFERROR(IF(PréstamoNoPagado*PréstamoPagado,AmortizaciónInterés,""), "") | H13: =IFERROR(IF(PréstamoNoPagado*PréstamoPagado,SaldoFinal,""), "")
B14: =IFERROR(IF(PréstamoNoPagado*PréstamoPagado,NúmeroDePago,""), "") | C14: =IFERROR(IF(PréstamoNoPagado*PréstamoPagado,FechaDePago,""), "") | D14: =IFERROR(IF(PréstamoNoPagado*PréstamoPagado,ValorPréstamo,""), "") | E14: =IFERROR(IF(PréstamoNoPagado*PréstamoPagado,PagoMensual,""), "") | F14: =IFERROR(IF(PréstamoNoPagado*PréstamoPagado,Capital,""), "") | G14: =IFERROR(IF(PréstamoNoPagado*PréstamoPagado,AmortizaciónInterés,""), "") | H14: =IFERROR(IF(PréstamoNoPagado*PréstamoPagado,SaldoFinal,""), "")
B15: =IFERROR(IF(PréstamoNoPagado*PréstamoPagado,NúmeroDePago,""), "") | C15: =IFERROR(IF(PréstamoNoPagado*PréstamoPagado,FechaDePago,""), "") | D15: =IFERROR(IF(PréstamoNoPagado*PréstamoPagado,ValorPréstamo,""), "") | E15: =IFERROR(IF(PréstamoNoPagado*PréstamoPagado,PagoMensual,""), "") | F15: =IFERROR(IF(PréstamoNoPagado*PréstamoPagado,Capital,""), "") | G15: =IFERROR(IF(PréstamoNoPagado*PréstamoPagado,AmortizaciónInterés,""), "") | H15: =IFERROR(IF(PréstamoNoPagado*PréstamoPagado,SaldoFinal,""), "")
B16: =IFERROR(IF(PréstamoNoPagado*PréstamoPagado,NúmeroDePago,""), "") | C16: =IFERROR(IF(PréstamoNoPagado*PréstamoPagado,FechaDePago,""), "") | D16: =IFERROR(IF(PréstamoNoPagado*PréstamoPagado,ValorPréstamo,""), "") | E16: =IFERROR(IF(PréstamoNoPagado*PréstamoPagado,PagoMensual,""), "") | F16: =IFERROR(IF(PréstamoNoPagado*PréstamoPagado,Capital,""), "") | G16: =IFERROR(IF(PréstamoNoPagado*PréstamoPagado,AmortizaciónInterés,""), "") | H16: =IFERROR(IF(PréstamoNoPagado*PréstamoPagado,SaldoFinal,""), "")
B17: =IFERROR(IF(PréstamoNoPagado*PréstamoPagado,NúmeroDePago,""), "") | C17: =IFERROR(IF(PréstamoNoPagado*PréstamoPagado,FechaDePago,""), "") | D17: =IFERROR(IF(PréstamoNoPagado*PréstamoPagado,ValorPréstamo,""), "") | E17: =IFERROR(IF(PréstamoNoPagado*PréstamoPagado,PagoMensual,""), "") | F17: =IFERROR(IF(PréstamoNoPagado*PréstamoPagado,Capital,""), "") | G17: =IFERROR(IF(PréstamoNoPagado*PréstamoPagado,AmortizaciónInterés,""), "") | H17: =IFERROR(IF(PréstamoNoPagado*PréstamoPagado,SaldoFinal,""), "")
B18: =IFERROR(IF(PréstamoNoPagado*PréstamoPagado,NúmeroDePago,""), "") | C18: =IFERROR(IF(PréstamoNoPagado*PréstamoPagado,FechaDePago,""), "") | D18: =IFERROR(IF(PréstamoNoPagado*PréstamoPagado,ValorPréstamo,""), "") | E18: =IFERROR(IF(PréstamoNoPagado*PréstamoPagado,PagoMensual,""), "") | F18: =IFERROR(IF(PréstamoNoPagado*PréstamoPagado,Capital,""), "") | G18: =IFERROR(IF(PréstamoNoPagado*PréstamoPagado,AmortizaciónInterés,""), "") | H18: =IFERROR(IF(PréstamoNoPagado*PréstamoPagado,SaldoFinal,""), "")
B19: =IFERROR(IF(PréstamoNoPagado*PréstamoPagado,NúmeroDePago,""), "") | C19: =IFERROR(IF(PréstamoNoPagado*PréstamoPagado,FechaDePago,""), "") | D19: =IFERROR(IF(PréstamoNoPagado*PréstamoPagado,ValorPréstamo,""), "") | E19: =IFERROR(IF(PréstamoNoPagado*PréstamoPagado,PagoMensual,""), "") | F19: =IFERROR(IF(PréstamoNoPagado*PréstamoPagado,Capital,""), "") | G19: =IFERROR(IF(PréstamoNoPagado*PréstamoPagado,AmortizaciónInterés,""), "") | H19: =IFERROR(IF(PréstamoNoPagado*PréstamoPagado,SaldoFinal,""), "")
B20: =IFERROR(IF(PréstamoNoPagado*PréstamoPagado,NúmeroDePago,""), "") | C20: =IFERROR(IF(PréstamoNoPagado*PréstamoPagado,FechaDePago,""), "") | D20: =IFERROR(IF(PréstamoNoPagado*PréstamoPagado,ValorPréstamo,""), "") | E20: =IFERROR(IF(PréstamoNoPagado*PréstamoPagado,PagoMensual,""), "") | F20: =IFERROR(IF(PréstamoNoPagado*PréstamoPagado,Capital,""), "") | G20: =IFERROR(IF(PréstamoNoPagado*PréstamoPagado,AmortizaciónInterés,""), "") | H20: =IFERROR(IF(PréstamoNoPagado*PréstamoPagado,SaldoFinal,""), "")
B21: =IFERROR(IF(PréstamoNoPagado*PréstamoPagado,NúmeroDePago,""), "") | C21: =IFERROR(IF(PréstamoNoPagado*PréstamoPagado,FechaDePago,""), "") | D21: =IFERROR(IF(PréstamoNoPagado*PréstamoPagado,ValorPréstamo,""), "") | E21: =IFERROR(IF(PréstamoNoPagado*PréstamoPagado,PagoMensual,""), "") | F21: =IFERROR(IF(PréstamoNoPagado*PréstamoPagado,Capital,""), "") | G21: =IFERROR(IF(PréstamoNoPagado*PréstamoPagado,AmortizaciónInterés,""), "") | H21: =IFERROR(IF(PréstamoNoPagado*PréstamoPagado,SaldoFinal,""), "")
